web/backtest.json
{"meta":{"strategy":"MA Cross (10/30)","initial_cash":100000},"metrics":{"total_return":0.3995972349,"cagr":0.1850400175,"annualized_vol":0.08752604187,"sharpe":1.983978731,"sortino":3.259919107,"max_drawdown":0.06663845631,"num_trades":11,"win_rate":0.6363636364,"profit_factor":4.330285627,"total_pnl":39707.03231},"bars":[[1,100.3292598],[2,100.3189942],[3,101.4591897],[4,102.0611345],[5,102.3020334],[6,102.0643451],[7,102.0773605],[8,101.1750483],[9,100.9166608],[10,101.4454918],[11,101.6365419],[12,101.9640111],[13,101.9790668],[14,102.2556635],[15,102.4393659],[16,102.3648019],[17,102.1383199],[18,102.4951132],[19,102.6866009],[20,102.9726112],[21,103.0980968],[22,103.9544138],[23,105.2647814],[24,105.0990471],[25,105.9063522],[26,104.8119936],[27,104.2587764],[28,104.819283],[29,105.1215126],[30,105.863229],[31,105.2166589],[32,105.0185078],[33,104.6145748],[34,104.957991],[35,104.7349197],[36,103.8820829],[37,103.8812474],[38,103.5489334],[39,104.1996184],[40,104.0098047],[41,103.8088537],[42,104.1162827],[43,104.7045402],[44,104.0223648],[45,105.4655564],[46,105.7743366],[47,106.5851913],[48,106.5578918],[49,106.4133848],[50,106.4836837],[51,106.7008299],[52,105.5701249],[53,105.0290356],[54,104.2821587],[55,103.8690742],[56,103.5886388],[57,102.8512231],[58,101.6483222],[59,101.7856106],[60,102.0710011],[61,101.8993466],[62,102.0404785],[63,101.9058479],[64,102.0232912],[65,102.442351],[66,102.062502],[67,101.323398],[68,100.9010117],[69,101.369275],[70,101.8285759],[71,101.9478974],[72,100.7452146],[73,101.1346694],[74,99.66241838],[75,99.89464634],[76,99.10403756],[77,99.0819936],[78,98.50046465],[79,98.12913475],[80,97.10817273],[81,97.50319076],[82,97.29696385],[83,97.48686646],[84,98.41719543],[85,97.66677354],[86,97.7248823],[87,97.73202501],[88,96.78754727],[89,97.07310409],[90,97.08953046],[91,97.25554215],[92,97.64264848],[93,98.15714329],[94,97.27078194],[95,96.70636116],[96,96.6669897],[97,95.86651425],[98,95.6713639],[99,96.19039896],[100,96.0672479],[101,95.64816184],[102,95.56384037],[103,95.96681763],[104,95.95219501],[105,95.49462325],[106,94.85211025],[107,94.28244633],[108,94.5511374],[109,94.66366956],[110,96.046862],[111,95.78367142],[112,95.4772819],[113,95.38322419],[114,95.35065692],[115,96.37508148],[116,95.39456047],[117,95.66019605],[118,95.93993505],[119,95.60249648],[120,96.39415169],[121,96.97443698],[122,96.82946696],[123,97.3499001],[124,97.62749684],[125,97.80088377],[126,98.07229247],[127,99.03172738],[128,100.2115432],[129,101.4184456],[130,100.2361476],[131,101.2896819],[132,102.8961602],[133,102.7899307],[134,102.963951],[135,102.8897458],[136,103.6176105],[137,103.8888977],[138,104.3795991],[139,104.4148773],[140,105.4059857],[141,105.8839245],[142,105.8593932],[143,106.1387203],[144,107.5188364],[145,108.241719],[146,108.1883233],[147,107.8015747],[148,108.4038322],[149,109.2199978],[150,109.0430723],[151,107.6922337],[152,108.0659551],[153,108.7244333],[154,109.1017095],[155,109.5814238],[156,109.1374583],[157,109.41895],[158,110.5710339],[159,110.2712526],[160,109.8945975],[161,110.105046],[162,110.0818159],[163,110.3370136],[164,110.3144029],[165,110.3481266],[166,110.1712013],[167,109.4297083],[168,109.8924707],[169,109.8266153],[170,109.7497126],[171,109.4591382],[172,109.8450225],[173,110.3286107],[174,110.5314016],[175,111.0330512],[176,109.7136979],[177,108.8384931],[178,108.0196515],[179,107.3019792],[180,105.3310259],[181,104.850897],[182,104.5916674],[183,103.6623637],[184,103.1182568],[185,103.4226452],[186,103.6689803],[187,102.2604531],[188,102.2328475],[189,102.0414351],[190,103.1254734],[191,101.9469055],[192,101.9922075],[193,101.9636295],[194,101.6827873],[195,101.9354575],[196,101.584367],[197,100.5164931],[198,101.0404366],[199,101.0269636],[200,101.2938205],[201,100.1156374],[202,99.88528254],[203,99.90458716],[204,100.5831106],[205,100.2377915],[206,98.97889843],[207,99.10491932],[208,99.13484196],[209,99.18536392],[210,98.96678327],[211,99.7655073],[212,100.9208338],[213,100.4602227],[214,99.80187734],[215,98.67791204],[216,98.55101253],[217,97.53236561],[218,96.6966043],[219,97.51428507],[220,96.82450057],[221,96.22209231],[222,95.73777351],[223,95.51199106],[224,96.10040904],[225,95.73703529],[226,96.07643735],[227,96.45980007],[228,95.49570709],[229,95.32051572],[230,94.53454696],[231,94.81012135],[232,94.5418462],[233,94.64945124],[234,94.51247011],[235,95.92116327],[236,95.20474069],[237,96.15640831],[238,95.67756935],[239,96.01320151],[240,96.36345961],[241,95.50429931],[242,95.99402525],[243,95.97193711],[244,96.84299416],[245,97.04953983],[246,98.07843857],[247,97.61103427],[248,97.69759437],[249,98.26547528],[250,98.12314586],[251,97.24750359],[252,96.78246708],[253,97.6064279],[254,97.41135192],[255,97.32310315],[256,98.70808036],[257,98.81566707],[258,98.19636207],[259,98.84889582],[260,99.2600935],[261,99.69147401],[262,101.2612288],[263,101.2654701],[264,102.5331152],[265,102.4434897],[266,102.752654],[267,102.8423631],[268,102.6720717],[269,102.5368117],[270,102.584441],[271,103.4469478],[272,103.3097707],[273,103.1906164],[274,104.6254886],[275,105.0940067],[276,105.0395356],[277,105.2163131],[278,107.24066],[279,108.265089],[280,108.9318358],[281,109.5560074],[282,109.8160243],[283,110.4741681],[284,110.8625209],[285,110.9937446],[286,110.3667899],[287,110.6258094],[288,110.8785267],[289,111.095989],[290,111.7130458],[291,111.9884128],[292,111.2080005],[293,110.6811935],[294,110.0307471],[295,109.830229],[296,109.4327732],[297,109.9442911],[298,108.8476164],[299,109.6078979],[300,108.7219626],[301,109.2881796],[302,108.400521],[303,107.1488081],[304,106.9013308],[305,107.4588491],[306,106.5874131],[307,106.2878846],[308,106.2988343],[309,106.8690802],[310,105.2709839],[311,106.0119286],[312,106.859221],[313,106.8115796],[314,106.1634955],[315,104.9672181],[316,104.9825775],[317,105.3459074],[318,105.1762863],[319,104.2337943],[320,104.4195498],[321,104.6245692],[322,103.8419808],[323,102.2294963],[324,102.3549484],[325,102.0611851],[326,100.34647],[327,99.93446675],[328,99.35602153],[329,99.73076269],[330,99.27788499],[331,99.24249799],[332,99.1193448],[333,96.92678106],[334,95.95895995],[335,97.09457839],[336,97.63095328],[337,97.65574065],[338,97.33869668],[339,98.2460214],[340,98.35681513],[341,98.58473008],[342,99.06281503],[343,99.05825527],[344,99.06565697],[345,98.82449563],[346,97.96470024],[347,97.84335057],[348,98.40893747],[349,97.75208556],[350,97.84240726],[351,97.04384217],[352,97.40426653],[353,97.39950036],[354,97.69522858],[355,98.4726891],[356,97.5761776],[357,98.85546638],[358,98.9329745],[359,98.59373691],[360,99.68132611],[361,99.19052125],[362,98.93913299],[363,98.92022386],[364,98.21296043],[365,97.31828697],[366,98.44787685],[367,99.18068441],[368,99.97148796],[369,100.6982129],[370,101.3243666],[371,102.0804817],[372,101.7222567],[373,100.5554743],[374,100.5383569],[375,100.3473026],[376,100.6993953],[377,100.8467228],[378,101.9818911],[379,102.5352705],[380,102.8817507],[381,103.1370577],[382,103.2919813],[383,102.9645664],[384,103.7793721],[385,103.5033285],[386,103.3813148],[387,103.253523],[388,104.4022749],[389,104.3214155],[390,104.5071045],[391,104.3278324],[392,104.3970301],[393,104.0169581],[394,104.5288034],[395,104.4171992],[396,103.8179056],[397,103.2156239],[398,102.9249054],[399,102.1044345],[400,102.0729985],[401,101.3266569],[402,102.4988334],[403,102.3782483],[404,102.0977826],[405,101.1524552],[406,102.2414937],[407,102.9272365],[408,103.061026],[409,102.3927353],[410,102.2254953],[411,103.1453716],[412,103.0692468],[413,103.9047521],[414,103.4943203],[415,104.1782653],[416,104.2634877],[417,103.8886951],[418,103.9218087],[419,103.9452199],[420,104.8035013],[421,105.150058],[422,105.0993918],[423,105.4244607],[424,105.8046427],[425,105.2368132],[426,104.2302266],[427,103.5565001],[428,102.9467451],[429,102.3193232],[430,101.5628954],[431,101.6186502],[432,101.5722556],[433,101.062269],[434,100.8012027],[435,100.4811608],[4
